ERROR 2025-02-19 11:49:10,322 exception 16 281473330573696 Invalid HTTP_HOST header: 'localhost:8000'. You may need to add 'localhost' to ALLOWED_HOSTS.
Traceback (most recent call last):
  File "/code/.venv/lib/python3.12/site-packages/asgiref/sync.py", line 518, in thread_handler
    raise exc_info[1]
  File "/code/.venv/lib/python3.12/site-packages/django/core/handlers/exception.py", line 42, in inner
    response = await get_response(request)
               ^^^^^^^^^^^^^^^^^^^^^^^^^^^
  File "/code/.venv/lib/python3.12/site-packages/django/utils/deprecation.py", line 141, in __acall__
    response = await sync_to_async(
               ^^^^^^^^^^^^^^^^^^^^
  File "/code/.venv/lib/python3.12/site-packages/asgiref/sync.py", line 468, in __call__
    ret = await asyncio.shield(exec_coro)
          ^^^^^^^^^^^^^^^^^^^^^^^^^^^^^^^
  File "/usr/local/lib/python3.12/concurrent/futures/thread.py", line 59, in run
    result = self.fn(*self.args, **self.kwargs)
             ^^^^^^^^^^^^^^^^^^^^^^^^^^^^^^^^^^
  File "/code/.venv/lib/python3.12/site-packages/asgiref/sync.py", line 522, in thread_handler
    return func(*args, **kwargs)
           ^^^^^^^^^^^^^^^^^^^^^
  File "/code/.venv/lib/python3.12/site-packages/django/middleware/security.py", line 28, in process_request
    host = self.redirect_host or request.get_host()
                                 ^^^^^^^^^^^^^^^^^^
  File "/code/.venv/lib/python3.12/site-packages/django/http/request.py", line 151, in get_host
    raise DisallowedHost(msg)
django.core.exceptions.DisallowedHost: Invalid HTTP_HOST header: 'localhost:8000'. You may need to add 'localhost' to ALLOWED_HOSTS.
WARNING 2025-02-19 11:49:10,549 log 16 281473330573696 Bad Request: /health/
ERROR 2025-02-19 11:49:40,569 exception 17 281473219031424 Invalid HTTP_HOST header: 'localhost:8000'. You may need to add 'localhost' to ALLOWED_HOSTS.
Traceback (most recent call last):
  File "/code/.venv/lib/python3.12/site-packages/asgiref/sync.py", line 518, in thread_handler
    raise exc_info[1]
  File "/code/.venv/lib/python3.12/site-packages/django/core/handlers/exception.py", line 42, in inner
    response = await get_response(request)
               ^^^^^^^^^^^^^^^^^^^^^^^^^^^
  File "/code/.venv/lib/python3.12/site-packages/django/utils/deprecation.py", line 141, in __acall__
    response = await sync_to_async(
               ^^^^^^^^^^^^^^^^^^^^
  File "/code/.venv/lib/python3.12/site-packages/asgiref/sync.py", line 468, in __call__
    ret = await asyncio.shield(exec_coro)
          ^^^^^^^^^^^^^^^^^^^^^^^^^^^^^^^
  File "/usr/local/lib/python3.12/concurrent/futures/thread.py", line 59, in run
    result = self.fn(*self.args, **self.kwargs)
             ^^^^^^^^^^^^^^^^^^^^^^^^^^^^^^^^^^
  File "/code/.venv/lib/python3.12/site-packages/asgiref/sync.py", line 522, in thread_handler
    return func(*args, **kwargs)
           ^^^^^^^^^^^^^^^^^^^^^
  File "/code/.venv/lib/python3.12/site-packages/django/middleware/security.py", line 28, in process_request
    host = self.redirect_host or request.get_host()
                                 ^^^^^^^^^^^^^^^^^^
  File "/code/.venv/lib/python3.12/site-packages/django/http/request.py", line 151, in get_host
    raise DisallowedHost(msg)
django.core.exceptions.DisallowedHost: Invalid HTTP_HOST header: 'localhost:8000'. You may need to add 'localhost' to ALLOWED_HOSTS.
WARNING 2025-02-19 11:49:40,800 log 17 281473219031424 Bad Request: /health/
ERROR 2025-02-19 11:50:52,597 exception 17 281473145631104 Invalid HTTP_HOST header: 'localhost:8000'. You may need to add 'localhost' to ALLOWED_HOSTS.
Traceback (most recent call last):
  File "/code/.venv/lib/python3.12/site-packages/asgiref/sync.py", line 518, in thread_handler
    raise exc_info[1]
  File "/code/.venv/lib/python3.12/site-packages/django/core/handlers/exception.py", line 42, in inner
    response = await get_response(request)
               ^^^^^^^^^^^^^^^^^^^^^^^^^^^
  File "/code/.venv/lib/python3.12/site-packages/django/utils/deprecation.py", line 141, in __acall__
    response = await sync_to_async(
               ^^^^^^^^^^^^^^^^^^^^
  File "/code/.venv/lib/python3.12/site-packages/asgiref/sync.py", line 468, in __call__
    ret = await asyncio.shield(exec_coro)
          ^^^^^^^^^^^^^^^^^^^^^^^^^^^^^^^
  File "/usr/local/lib/python3.12/concurrent/futures/thread.py", line 59, in run
    result = self.fn(*self.args, **self.kwargs)
             ^^^^^^^^^^^^^^^^^^^^^^^^^^^^^^^^^^
  File "/code/.venv/lib/python3.12/site-packages/asgiref/sync.py", line 522, in thread_handler
    return func(*args, **kwargs)
           ^^^^^^^^^^^^^^^^^^^^^
  File "/code/.venv/lib/python3.12/site-packages/django/middleware/security.py", line 28, in process_request
    host = self.redirect_host or request.get_host()
                                 ^^^^^^^^^^^^^^^^^^
  File "/code/.venv/lib/python3.12/site-packages/django/http/request.py", line 151, in get_host
    raise DisallowedHost(msg)
django.core.exceptions.DisallowedHost: Invalid HTTP_HOST header: 'localhost:8000'. You may need to add 'localhost' to ALLOWED_HOSTS.
WARNING 2025-02-19 11:50:52,867 log 17 281473145631104 Bad Request: /health/
ERROR 2025-02-19 11:51:22,911 exception 17 281473145631104 Invalid HTTP_HOST header: 'localhost:8000'. You may need to add 'localhost' to ALLOWED_HOSTS.
Traceback (most recent call last):
  File "/code/.venv/lib/python3.12/site-packages/asgiref/sync.py", line 518, in thread_handler
    raise exc_info[1]
  File "/code/.venv/lib/python3.12/site-packages/django/core/handlers/exception.py", line 42, in inner
    response = await get_response(request)
               ^^^^^^^^^^^^^^^^^^^^^^^^^^^
  File "/code/.venv/lib/python3.12/site-packages/django/utils/deprecation.py", line 141, in __acall__
    response = await sync_to_async(
               ^^^^^^^^^^^^^^^^^^^^
  File "/code/.venv/lib/python3.12/site-packages/asgiref/sync.py", line 468, in __call__
    ret = await asyncio.shield(exec_coro)
          ^^^^^^^^^^^^^^^^^^^^^^^^^^^^^^^
  File "/usr/local/lib/python3.12/concurrent/futures/thread.py", line 59, in run
    result = self.fn(*self.args, **self.kwargs)
             ^^^^^^^^^^^^^^^^^^^^^^^^^^^^^^^^^^
  File "/code/.venv/lib/python3.12/site-packages/asgiref/sync.py", line 522, in thread_handler
    return func(*args, **kwargs)
           ^^^^^^^^^^^^^^^^^^^^^
  File "/code/.venv/lib/python3.12/site-packages/django/middleware/security.py", line 28, in process_request
    host = self.redirect_host or request.get_host()
                                 ^^^^^^^^^^^^^^^^^^
  File "/code/.venv/lib/python3.12/site-packages/django/http/request.py", line 151, in get_host
    raise DisallowedHost(msg)
django.core.exceptions.DisallowedHost: Invalid HTTP_HOST header: 'localhost:8000'. You may need to add 'localhost' to ALLOWED_HOSTS.
WARNING 2025-02-19 11:51:22,913 log 17 281473145631104 Bad Request: /health/
ERROR 2025-02-19 11:51:52,961 exception 17 281473145631104 Invalid HTTP_HOST header: 'localhost:8000'. You may need to add 'localhost' to ALLOWED_HOSTS.
Traceback (most recent call last):
  File "/code/.venv/lib/python3.12/site-packages/asgiref/sync.py", line 518, in thread_handler
    raise exc_info[1]
  File "/code/.venv/lib/python3.12/site-packages/django/core/handlers/exception.py", line 42, in inner
    response = await get_response(request)
               ^^^^^^^^^^^^^^^^^^^^^^^^^^^
  File "/code/.venv/lib/python3.12/site-packages/django/utils/deprecation.py", line 141, in __acall__
    response = await sync_to_async(
               ^^^^^^^^^^^^^^^^^^^^
  File "/code/.venv/lib/python3.12/site-packages/asgiref/sync.py", line 468, in __call__
    ret = await asyncio.shield(exec_coro)
          ^^^^^^^^^^^^^^^^^^^^^^^^^^^^^^^
  File "/usr/local/lib/python3.12/concurrent/futures/thread.py", line 59, in run
    result = self.fn(*self.args, **self.kwargs)
             ^^^^^^^^^^^^^^^^^^^^^^^^^^^^^^^^^^
  File "/code/.venv/lib/python3.12/site-packages/asgiref/sync.py", line 522, in thread_handler
    return func(*args, **kwargs)
           ^^^^^^^^^^^^^^^^^^^^^
  File "/code/.venv/lib/python3.12/site-packages/django/middleware/security.py", line 28, in process_request
    host = self.redirect_host or request.get_host()
                                 ^^^^^^^^^^^^^^^^^^
  File "/code/.venv/lib/python3.12/site-packages/django/http/request.py", line 151, in get_host
    raise DisallowedHost(msg)
django.core.exceptions.DisallowedHost: Invalid HTTP_HOST header: 'localhost:8000'. You may need to add 'localhost' to ALLOWED_HOSTS.
WARNING 2025-02-19 11:51:52,962 log 17 281473145631104 Bad Request: /health/
ERROR 2025-02-19 11:52:23,006 exception 17 281473145631104 Invalid HTTP_HOST header: 'localhost:8000'. You may need to add 'localhost' to ALLOWED_HOSTS.
Traceback (most recent call last):
  File "/code/.venv/lib/python3.12/site-packages/asgiref/sync.py", line 518, in thread_handler
    raise exc_info[1]
  File "/code/.venv/lib/python3.12/site-packages/django/core/handlers/exception.py", line 42, in inner
    response = await get_response(request)
               ^^^^^^^^^^^^^^^^^^^^^^^^^^^
  File "/code/.venv/lib/python3.12/site-packages/django/utils/deprecation.py", line 141, in __acall__
    response = await sync_to_async(
               ^^^^^^^^^^^^^^^^^^^^
  File "/code/.venv/lib/python3.12/site-packages/asgiref/sync.py", line 468, in __call__
    ret = await asyncio.shield(exec_coro)
          ^^^^^^^^^^^^^^^^^^^^^^^^^^^^^^^
  File "/usr/local/lib/python3.12/concurrent/futures/thread.py", line 59, in run
    result = self.fn(*self.args, **self.kwargs)
             ^^^^^^^^^^^^^^^^^^^^^^^^^^^^^^^^^^
  File "/code/.venv/lib/python3.12/site-packages/asgiref/sync.py", line 522, in thread_handler
    return func(*args, **kwargs)
           ^^^^^^^^^^^^^^^^^^^^^
  File "/code/.venv/lib/python3.12/site-packages/django/middleware/security.py", line 28, in process_request
    host = self.redirect_host or request.get_host()
                                 ^^^^^^^^^^^^^^^^^^
  File "/code/.venv/lib/python3.12/site-packages/django/http/request.py", line 151, in get_host
    raise DisallowedHost(msg)
django.core.exceptions.DisallowedHost: Invalid HTTP_HOST header: 'localhost:8000'. You may need to add 'localhost' to ALLOWED_HOSTS.
WARNING 2025-02-19 11:52:23,007 log 17 281473145631104 Bad Request: /health/
ERROR 2025-02-19 11:52:53,914 exception 18 281473673064832 Invalid HTTP_HOST header: 'localhost:8000'. You may need to add 'localhost' to ALLOWED_HOSTS.
Traceback (most recent call last):
  File "/code/.venv/lib/python3.12/site-packages/asgiref/sync.py", line 518, in thread_handler
    raise exc_info[1]
  File "/code/.venv/lib/python3.12/site-packages/django/core/handlers/exception.py", line 42, in inner
    response = await get_response(request)
               ^^^^^^^^^^^^^^^^^^^^^^^^^^^
  File "/code/.venv/lib/python3.12/site-packages/django/utils/deprecation.py", line 141, in __acall__
    response = await sync_to_async(
               ^^^^^^^^^^^^^^^^^^^^
  File "/code/.venv/lib/python3.12/site-packages/asgiref/sync.py", line 468, in __call__
    ret = await asyncio.shield(exec_coro)
          ^^^^^^^^^^^^^^^^^^^^^^^^^^^^^^^
  File "/usr/local/lib/python3.12/concurrent/futures/thread.py", line 59, in run
    result = self.fn(*self.args, **self.kwargs)
             ^^^^^^^^^^^^^^^^^^^^^^^^^^^^^^^^^^
  File "/code/.venv/lib/python3.12/site-packages/asgiref/sync.py", line 522, in thread_handler
    return func(*args, **kwargs)
           ^^^^^^^^^^^^^^^^^^^^^
  File "/code/.venv/lib/python3.12/site-packages/django/middleware/security.py", line 28, in process_request
    host = self.redirect_host or request.get_host()
                                 ^^^^^^^^^^^^^^^^^^
  File "/code/.venv/lib/python3.12/site-packages/django/http/request.py", line 151, in get_host
    raise DisallowedHost(msg)
django.core.exceptions.DisallowedHost: Invalid HTTP_HOST header: 'localhost:8000'. You may need to add 'localhost' to ALLOWED_HOSTS.
WARNING 2025-02-19 11:52:54,164 log 18 281473673064832 Bad Request: /health/
ERROR 2025-02-19 11:53:16,890 exception 17 281473423372672 Invalid HTTP_HOST header: 'localhost:8000'. You may need to add 'localhost' to ALLOWED_HOSTS.
Traceback (most recent call last):
  File "/code/.venv/lib/python3.12/site-packages/asgiref/sync.py", line 518, in thread_handler
    raise exc_info[1]
  File "/code/.venv/lib/python3.12/site-packages/django/core/handlers/exception.py", line 42, in inner
    response = await get_response(request)
               ^^^^^^^^^^^^^^^^^^^^^^^^^^^
  File "/code/.venv/lib/python3.12/site-packages/django/utils/deprecation.py", line 141, in __acall__
    response = await sync_to_async(
               ^^^^^^^^^^^^^^^^^^^^
  File "/code/.venv/lib/python3.12/site-packages/asgiref/sync.py", line 468, in __call__
    ret = await asyncio.shield(exec_coro)
          ^^^^^^^^^^^^^^^^^^^^^^^^^^^^^^^
  File "/usr/local/lib/python3.12/concurrent/futures/thread.py", line 59, in run
    result = self.fn(*self.args, **self.kwargs)
             ^^^^^^^^^^^^^^^^^^^^^^^^^^^^^^^^^^
  File "/code/.venv/lib/python3.12/site-packages/asgiref/sync.py", line 522, in thread_handler
    return func(*args, **kwargs)
           ^^^^^^^^^^^^^^^^^^^^^
  File "/code/.venv/lib/python3.12/site-packages/django/middleware/security.py", line 28, in process_request
    host = self.redirect_host or request.get_host()
                                 ^^^^^^^^^^^^^^^^^^
  File "/code/.venv/lib/python3.12/site-packages/django/http/request.py", line 151, in get_host
    raise DisallowedHost(msg)
django.core.exceptions.DisallowedHost: Invalid HTTP_HOST header: 'localhost:8000'. You may need to add 'localhost' to ALLOWED_HOSTS.
WARNING 2025-02-19 11:53:17,126 log 17 281473423372672 Bad Request: /health/
ERROR 2025-02-19 11:53:55,086 exception 18 281473280438656 Invalid HTTP_HOST header: 'localhost:8000'. You may need to add 'localhost' to ALLOWED_HOSTS.
Traceback (most recent call last):
  File "/code/.venv/lib/python3.12/site-packages/asgiref/sync.py", line 518, in thread_handler
    raise exc_info[1]
  File "/code/.venv/lib/python3.12/site-packages/django/core/handlers/exception.py", line 42, in inner
    response = await get_response(request)
               ^^^^^^^^^^^^^^^^^^^^^^^^^^^
  File "/code/.venv/lib/python3.12/site-packages/django/utils/deprecation.py", line 141, in __acall__
    response = await sync_to_async(
               ^^^^^^^^^^^^^^^^^^^^
  File "/code/.venv/lib/python3.12/site-packages/asgiref/sync.py", line 468, in __call__
    ret = await asyncio.shield(exec_coro)
          ^^^^^^^^^^^^^^^^^^^^^^^^^^^^^^^
  File "/usr/local/lib/python3.12/concurrent/futures/thread.py", line 59, in run
    result = self.fn(*self.args, **self.kwargs)
             ^^^^^^^^^^^^^^^^^^^^^^^^^^^^^^^^^^
  File "/code/.venv/lib/python3.12/site-packages/asgiref/sync.py", line 522, in thread_handler
    return func(*args, **kwargs)
           ^^^^^^^^^^^^^^^^^^^^^
  File "/code/.venv/lib/python3.12/site-packages/django/middleware/security.py", line 28, in process_request
    host = self.redirect_host or request.get_host()
                                 ^^^^^^^^^^^^^^^^^^
  File "/code/.venv/lib/python3.12/site-packages/django/http/request.py", line 151, in get_host
    raise DisallowedHost(msg)
django.core.exceptions.DisallowedHost: Invalid HTTP_HOST header: 'localhost:8000'. You may need to add 'localhost' to ALLOWED_HOSTS.
WARNING 2025-02-19 11:53:55,338 log 18 281473280438656 Bad Request: /health/
ERROR 2025-02-19 11:54:16,610 exception 19 281473259532672 Invalid HTTP_HOST header: 'localhost:8000'. You may need to add 'localhost' to ALLOWED_HOSTS.
Traceback (most recent call last):
  File "/code/.venv/lib/python3.12/site-packages/asgiref/sync.py", line 518, in thread_handler
    raise exc_info[1]
  File "/code/.venv/lib/python3.12/site-packages/django/core/handlers/exception.py", line 42, in inner
    response = await get_response(request)
               ^^^^^^^^^^^^^^^^^^^^^^^^^^^
  File "/code/.venv/lib/python3.12/site-packages/django/utils/deprecation.py", line 141, in __acall__
    response = await sync_to_async(
               ^^^^^^^^^^^^^^^^^^^^
  File "/code/.venv/lib/python3.12/site-packages/asgiref/sync.py", line 468, in __call__
    ret = await asyncio.shield(exec_coro)
          ^^^^^^^^^^^^^^^^^^^^^^^^^^^^^^^
  File "/usr/local/lib/python3.12/concurrent/futures/thread.py", line 59, in run
    result = self.fn(*self.args, **self.kwargs)
             ^^^^^^^^^^^^^^^^^^^^^^^^^^^^^^^^^^
  File "/code/.venv/lib/python3.12/site-packages/asgiref/sync.py", line 522, in thread_handler
    return func(*args, **kwargs)
           ^^^^^^^^^^^^^^^^^^^^^
  File "/code/.venv/lib/python3.12/site-packages/django/middleware/security.py", line 28, in process_request
    host = self.redirect_host or request.get_host()
                                 ^^^^^^^^^^^^^^^^^^
  File "/code/.venv/lib/python3.12/site-packages/django/http/request.py", line 151, in get_host
    raise DisallowedHost(msg)
django.core.exceptions.DisallowedHost: Invalid HTTP_HOST header: 'localhost:8000'. You may need to add 'localhost' to ALLOWED_HOSTS.
WARNING 2025-02-19 11:54:16,838 log 19 281473259532672 Bad Request: /health/
ERROR 2025-02-19 11:54:34,069 exception 17 281473307898240 Invalid HTTP_HOST header: 'localhost:8000'. You may need to add 'localhost' to ALLOWED_HOSTS.
Traceback (most recent call last):
  File "/code/.venv/lib/python3.12/site-packages/asgiref/sync.py", line 518, in thread_handler
    raise exc_info[1]
  File "/code/.venv/lib/python3.12/site-packages/django/core/handlers/exception.py", line 42, in inner
    response = await get_response(request)
               ^^^^^^^^^^^^^^^^^^^^^^^^^^^
  File "/code/.venv/lib/python3.12/site-packages/django/utils/deprecation.py", line 141, in __acall__
    response = await sync_to_async(
               ^^^^^^^^^^^^^^^^^^^^
  File "/code/.venv/lib/python3.12/site-packages/asgiref/sync.py", line 468, in __call__
    ret = await asyncio.shield(exec_coro)
          ^^^^^^^^^^^^^^^^^^^^^^^^^^^^^^^
  File "/usr/local/lib/python3.12/concurrent/futures/thread.py", line 59, in run
    result = self.fn(*self.args, **self.kwargs)
             ^^^^^^^^^^^^^^^^^^^^^^^^^^^^^^^^^^
  File "/code/.venv/lib/python3.12/site-packages/asgiref/sync.py", line 522, in thread_handler
    return func(*args, **kwargs)
           ^^^^^^^^^^^^^^^^^^^^^
  File "/code/.venv/lib/python3.12/site-packages/django/middleware/security.py", line 28, in process_request
    host = self.redirect_host or request.get_host()
                                 ^^^^^^^^^^^^^^^^^^
  File "/code/.venv/lib/python3.12/site-packages/django/http/request.py", line 151, in get_host
    raise DisallowedHost(msg)
django.core.exceptions.DisallowedHost: Invalid HTTP_HOST header: 'localhost:8000'. You may need to add 'localhost' to ALLOWED_HOSTS.
WARNING 2025-02-19 11:54:34,328 log 17 281473307898240 Bad Request: /health/
ERROR 2025-02-19 11:54:55,656 exception 17 281473307898240 Invalid HTTP_HOST header: 'localhost:8000'. You may need to add 'localhost' to ALLOWED_HOSTS.
Traceback (most recent call last):
  File "/code/.venv/lib/python3.12/site-packages/asgiref/sync.py", line 518, in thread_handler
    raise exc_info[1]
  File "/code/.venv/lib/python3.12/site-packages/django/core/handlers/exception.py", line 42, in inner
    response = await get_response(request)
               ^^^^^^^^^^^^^^^^^^^^^^^^^^^
  File "/code/.venv/lib/python3.12/site-packages/django/utils/deprecation.py", line 141, in __acall__
    response = await sync_to_async(
               ^^^^^^^^^^^^^^^^^^^^
  File "/code/.venv/lib/python3.12/site-packages/asgiref/sync.py", line 468, in __call__
    ret = await asyncio.shield(exec_coro)
          ^^^^^^^^^^^^^^^^^^^^^^^^^^^^^^^
  File "/usr/local/lib/python3.12/concurrent/futures/thread.py", line 59, in run
    result = self.fn(*self.args, **self.kwargs)
             ^^^^^^^^^^^^^^^^^^^^^^^^^^^^^^^^^^
  File "/code/.venv/lib/python3.12/site-packages/asgiref/sync.py", line 522, in thread_handler
    return func(*args, **kwargs)
           ^^^^^^^^^^^^^^^^^^^^^
  File "/code/.venv/lib/python3.12/site-packages/django/middleware/security.py", line 28, in process_request
    host = self.redirect_host or request.get_host()
                                 ^^^^^^^^^^^^^^^^^^
  File "/code/.venv/lib/python3.12/site-packages/django/http/request.py", line 151, in get_host
    raise DisallowedHost(msg)
django.core.exceptions.DisallowedHost: Invalid HTTP_HOST header: 'localhost:8000'. You may need to add 'localhost' to ALLOWED_HOSTS.
WARNING 2025-02-19 11:54:55,657 log 17 281473307898240 Bad Request: /health/
ERROR 2025-02-19 11:55:30,624 exception 17 281472706408832 Invalid HTTP_HOST header: 'localhost:8000'. You may need to add 'localhost' to ALLOWED_HOSTS.
Traceback (most recent call last):
  File "/code/.venv/lib/python3.12/site-packages/asgiref/sync.py", line 518, in thread_handler
    raise exc_info[1]
  File "/code/.venv/lib/python3.12/site-packages/django/core/handlers/exception.py", line 42, in inner
    response = await get_response(request)
               ^^^^^^^^^^^^^^^^^^^^^^^^^^^
  File "/code/.venv/lib/python3.12/site-packages/django/utils/deprecation.py", line 141, in __acall__
    response = await sync_to_async(
               ^^^^^^^^^^^^^^^^^^^^
  File "/code/.venv/lib/python3.12/site-packages/asgiref/sync.py", line 468, in __call__
    ret = await asyncio.shield(exec_coro)
          ^^^^^^^^^^^^^^^^^^^^^^^^^^^^^^^
  File "/usr/local/lib/python3.12/concurrent/futures/thread.py", line 59, in run
    result = self.fn(*self.args, **self.kwargs)
             ^^^^^^^^^^^^^^^^^^^^^^^^^^^^^^^^^^
  File "/code/.venv/lib/python3.12/site-packages/asgiref/sync.py", line 522, in thread_handler
    return func(*args, **kwargs)
           ^^^^^^^^^^^^^^^^^^^^^
  File "/code/.venv/lib/python3.12/site-packages/django/middleware/security.py", line 28, in process_request
    host = self.redirect_host or request.get_host()
                                 ^^^^^^^^^^^^^^^^^^
  File "/code/.venv/lib/python3.12/site-packages/django/http/request.py", line 151, in get_host
    raise DisallowedHost(msg)
django.core.exceptions.DisallowedHost: Invalid HTTP_HOST header: 'localhost:8000'. You may need to add 'localhost' to ALLOWED_HOSTS.
WARNING 2025-02-19 11:55:30,859 log 17 281472706408832 Bad Request: /health/
ERROR 2025-02-19 11:55:42,130 exception 17 281472742322560 Invalid HTTP_HOST header: 'localhost:8000'. You may need to add 'localhost' to ALLOWED_HOSTS.
Traceback (most recent call last):
  File "/code/.venv/lib/python3.12/site-packages/asgiref/sync.py", line 518, in thread_handler
    raise exc_info[1]
  File "/code/.venv/lib/python3.12/site-packages/django/core/handlers/exception.py", line 42, in inner
    response = await get_response(request)
               ^^^^^^^^^^^^^^^^^^^^^^^^^^^
  File "/code/.venv/lib/python3.12/site-packages/django/utils/deprecation.py", line 141, in __acall__
    response = await sync_to_async(
               ^^^^^^^^^^^^^^^^^^^^
  File "/code/.venv/lib/python3.12/site-packages/asgiref/sync.py", line 468, in __call__
    ret = await asyncio.shield(exec_coro)
          ^^^^^^^^^^^^^^^^^^^^^^^^^^^^^^^
  File "/usr/local/lib/python3.12/concurrent/futures/thread.py", line 59, in run
    result = self.fn(*self.args, **self.kwargs)
             ^^^^^^^^^^^^^^^^^^^^^^^^^^^^^^^^^^
  File "/code/.venv/lib/python3.12/site-packages/asgiref/sync.py", line 522, in thread_handler
    return func(*args, **kwargs)
           ^^^^^^^^^^^^^^^^^^^^^
  File "/code/.venv/lib/python3.12/site-packages/django/middleware/security.py", line 28, in process_request
    host = self.redirect_host or request.get_host()
                                 ^^^^^^^^^^^^^^^^^^
  File "/code/.venv/lib/python3.12/site-packages/django/http/request.py", line 151, in get_host
    raise DisallowedHost(msg)
django.core.exceptions.DisallowedHost: Invalid HTTP_HOST header: 'localhost:8000'. You may need to add 'localhost' to ALLOWED_HOSTS.
WARNING 2025-02-19 11:55:42,385 log 17 281472742322560 Bad Request: /health/
ERROR 2025-02-19 11:56:04,983 exception 17 281472742322560 Invalid HTTP_HOST header: 'localhost:8000'. You may need to add 'localhost' to ALLOWED_HOSTS.
Traceback (most recent call last):
  File "/code/.venv/lib/python3.12/site-packages/asgiref/sync.py", line 518, in thread_handler
    raise exc_info[1]
  File "/code/.venv/lib/python3.12/site-packages/django/core/handlers/exception.py", line 42, in inner
    response = await get_response(request)
               ^^^^^^^^^^^^^^^^^^^^^^^^^^^
  File "/code/.venv/lib/python3.12/site-packages/django/utils/deprecation.py", line 141, in __acall__
    response = await sync_to_async(
               ^^^^^^^^^^^^^^^^^^^^
  File "/code/.venv/lib/python3.12/site-packages/asgiref/sync.py", line 468, in __call__
    ret = await asyncio.shield(exec_coro)
          ^^^^^^^^^^^^^^^^^^^^^^^^^^^^^^^
  File "/usr/local/lib/python3.12/concurrent/futures/thread.py", line 59, in run
    result = self.fn(*self.args, **self.kwargs)
             ^^^^^^^^^^^^^^^^^^^^^^^^^^^^^^^^^^
  File "/code/.venv/lib/python3.12/site-packages/asgiref/sync.py", line 522, in thread_handler
    return func(*args, **kwargs)
           ^^^^^^^^^^^^^^^^^^^^^
  File "/code/.venv/lib/python3.12/site-packages/django/middleware/security.py", line 28, in process_request
    host = self.redirect_host or request.get_host()
                                 ^^^^^^^^^^^^^^^^^^
  File "/code/.venv/lib/python3.12/site-packages/django/http/request.py", line 151, in get_host
    raise DisallowedHost(msg)
django.core.exceptions.DisallowedHost: Invalid HTTP_HOST header: 'localhost:8000'. You may need to add 'localhost' to ALLOWED_HOSTS.
WARNING 2025-02-19 11:56:04,985 log 17 281472742322560 Bad Request: /health/
ERROR 2025-02-19 11:56:17,320 exception 17 281473290531200 Invalid HTTP_HOST header: 'localhost:8000'. You may need to add 'localhost' to ALLOWED_HOSTS.
Traceback (most recent call last):
  File "/code/.venv/lib/python3.12/site-packages/asgiref/sync.py", line 518, in thread_handler
    raise exc_info[1]
  File "/code/.venv/lib/python3.12/site-packages/django/core/handlers/exception.py", line 42, in inner
    response = await get_response(request)
               ^^^^^^^^^^^^^^^^^^^^^^^^^^^
  File "/code/.venv/lib/python3.12/site-packages/django/utils/deprecation.py", line 141, in __acall__
    response = await sync_to_async(
               ^^^^^^^^^^^^^^^^^^^^
  File "/code/.venv/lib/python3.12/site-packages/asgiref/sync.py", line 468, in __call__
    ret = await asyncio.shield(exec_coro)
          ^^^^^^^^^^^^^^^^^^^^^^^^^^^^^^^
  File "/usr/local/lib/python3.12/concurrent/futures/thread.py", line 59, in run
    result = self.fn(*self.args, **self.kwargs)
             ^^^^^^^^^^^^^^^^^^^^^^^^^^^^^^^^^^
  File "/code/.venv/lib/python3.12/site-packages/asgiref/sync.py", line 522, in thread_handler
    return func(*args, **kwargs)
           ^^^^^^^^^^^^^^^^^^^^^
  File "/code/.venv/lib/python3.12/site-packages/django/middleware/security.py", line 28, in process_request
    host = self.redirect_host or request.get_host()
                                 ^^^^^^^^^^^^^^^^^^
  File "/code/.venv/lib/python3.12/site-packages/django/http/request.py", line 151, in get_host
    raise DisallowedHost(msg)
django.core.exceptions.DisallowedHost: Invalid HTTP_HOST header: 'localhost:8000'. You may need to add 'localhost' to ALLOWED_HOSTS.
WARNING 2025-02-19 11:56:17,560 log 17 281473290531200 Bad Request: /health/
ERROR 2025-02-19 11:56:40,007 exception 19 281473141436800 Invalid HTTP_HOST header: 'localhost:8000'. You may need to add 'localhost' to ALLOWED_HOSTS.
Traceback (most recent call last):
  File "/code/.venv/lib/python3.12/site-packages/asgiref/sync.py", line 518, in thread_handler
    raise exc_info[1]
  File "/code/.venv/lib/python3.12/site-packages/django/core/handlers/exception.py", line 42, in inner
    response = await get_response(request)
               ^^^^^^^^^^^^^^^^^^^^^^^^^^^
  File "/code/.venv/lib/python3.12/site-packages/django/utils/deprecation.py", line 141, in __acall__
    response = await sync_to_async(
               ^^^^^^^^^^^^^^^^^^^^
  File "/code/.venv/lib/python3.12/site-packages/asgiref/sync.py", line 468, in __call__
    ret = await asyncio.shield(exec_coro)
          ^^^^^^^^^^^^^^^^^^^^^^^^^^^^^^^
  File "/usr/local/lib/python3.12/concurrent/futures/thread.py", line 59, in run
    result = self.fn(*self.args, **self.kwargs)
             ^^^^^^^^^^^^^^^^^^^^^^^^^^^^^^^^^^
  File "/code/.venv/lib/python3.12/site-packages/asgiref/sync.py", line 522, in thread_handler
    return func(*args, **kwargs)
           ^^^^^^^^^^^^^^^^^^^^^
  File "/code/.venv/lib/python3.12/site-packages/django/middleware/security.py", line 28, in process_request
    host = self.redirect_host or request.get_host()
                                 ^^^^^^^^^^^^^^^^^^
  File "/code/.venv/lib/python3.12/site-packages/django/http/request.py", line 151, in get_host
    raise DisallowedHost(msg)
django.core.exceptions.DisallowedHost: Invalid HTTP_HOST header: 'localhost:8000'. You may need to add 'localhost' to ALLOWED_HOSTS.
WARNING 2025-02-19 11:56:40,237 log 19 281473141436800 Bad Request: /health/
ERROR 2025-02-19 11:56:58,692 exception 18 281473212805504 Invalid HTTP_HOST header: 'localhost:8000'. You may need to add 'localhost' to ALLOWED_HOSTS.
Traceback (most recent call last):
  File "/code/.venv/lib/python3.12/site-packages/asgiref/sync.py", line 518, in thread_handler
    raise exc_info[1]
  File "/code/.venv/lib/python3.12/site-packages/django/core/handlers/exception.py", line 42, in inner
    response = await get_response(request)
               ^^^^^^^^^^^^^^^^^^^^^^^^^^^
  File "/code/.venv/lib/python3.12/site-packages/django/utils/deprecation.py", line 141, in __acall__
    response = await sync_to_async(
               ^^^^^^^^^^^^^^^^^^^^
  File "/code/.venv/lib/python3.12/site-packages/asgiref/sync.py", line 468, in __call__
    ret = await asyncio.shield(exec_coro)
          ^^^^^^^^^^^^^^^^^^^^^^^^^^^^^^^
  File "/usr/local/lib/python3.12/concurrent/futures/thread.py", line 59, in run
    result = self.fn(*self.args, **self.kwargs)
             ^^^^^^^^^^^^^^^^^^^^^^^^^^^^^^^^^^
  File "/code/.venv/lib/python3.12/site-packages/asgiref/sync.py", line 522, in thread_handler
    return func(*args, **kwargs)
           ^^^^^^^^^^^^^^^^^^^^^
  File "/code/.venv/lib/python3.12/site-packages/django/middleware/security.py", line 28, in process_request
    host = self.redirect_host or request.get_host()
                                 ^^^^^^^^^^^^^^^^^^
  File "/code/.venv/lib/python3.12/site-packages/django/http/request.py", line 151, in get_host
    raise DisallowedHost(msg)
django.core.exceptions.DisallowedHost: Invalid HTTP_HOST header: 'localhost:8000'. You may need to add 'localhost' to ALLOWED_HOSTS.
WARNING 2025-02-19 11:56:58,954 log 18 281473212805504 Bad Request: /health/
ERROR 2025-02-19 11:57:22,590 exception 18 281473212805504 Invalid HTTP_HOST header: 'localhost:8000'. You may need to add 'localhost' to ALLOWED_HOSTS.
Traceback (most recent call last):
  File "/code/.venv/lib/python3.12/site-packages/asgiref/sync.py", line 518, in thread_handler
    raise exc_info[1]
  File "/code/.venv/lib/python3.12/site-packages/django/core/handlers/exception.py", line 42, in inner
    response = await get_response(request)
               ^^^^^^^^^^^^^^^^^^^^^^^^^^^
  File "/code/.venv/lib/python3.12/site-packages/django/utils/deprecation.py", line 141, in __acall__
    response = await sync_to_async(
               ^^^^^^^^^^^^^^^^^^^^
  File "/code/.venv/lib/python3.12/site-packages/asgiref/sync.py", line 468, in __call__
    ret = await asyncio.shield(exec_coro)
          ^^^^^^^^^^^^^^^^^^^^^^^^^^^^^^^
  File "/usr/local/lib/python3.12/concurrent/futures/thread.py", line 59, in run
    result = self.fn(*self.args, **self.kwargs)
             ^^^^^^^^^^^^^^^^^^^^^^^^^^^^^^^^^^
  File "/code/.venv/lib/python3.12/site-packages/asgiref/sync.py", line 522, in thread_handler
    return func(*args, **kwargs)
           ^^^^^^^^^^^^^^^^^^^^^
  File "/code/.venv/lib/python3.12/site-packages/django/middleware/security.py", line 28, in process_request
    host = self.redirect_host or request.get_host()
                                 ^^^^^^^^^^^^^^^^^^
  File "/code/.venv/lib/python3.12/site-packages/django/http/request.py", line 151, in get_host
    raise DisallowedHost(msg)
django.core.exceptions.DisallowedHost: Invalid HTTP_HOST header: 'localhost:8000'. You may need to add 'localhost' to ALLOWED_HOSTS.
WARNING 2025-02-19 11:57:22,591 log 18 281473212805504 Bad Request: /health/
ERROR 2025-02-19 11:57:49,733 exception 16 281473605300608 Invalid HTTP_HOST header: 'localhost:8000'. You may need to add 'localhost' to ALLOWED_HOSTS.
Traceback (most recent call last):
  File "/code/.venv/lib/python3.12/site-packages/asgiref/sync.py", line 518, in thread_handler
    raise exc_info[1]
  File "/code/.venv/lib/python3.12/site-packages/django/core/handlers/exception.py", line 42, in inner
    response = await get_response(request)
               ^^^^^^^^^^^^^^^^^^^^^^^^^^^
  File "/code/.venv/lib/python3.12/site-packages/django/utils/deprecation.py", line 141, in __acall__
    response = await sync_to_async(
               ^^^^^^^^^^^^^^^^^^^^
  File "/code/.venv/lib/python3.12/site-packages/asgiref/sync.py", line 468, in __call__
    ret = await asyncio.shield(exec_coro)
          ^^^^^^^^^^^^^^^^^^^^^^^^^^^^^^^
  File "/usr/local/lib/python3.12/concurrent/futures/thread.py", line 59, in run
    result = self.fn(*self.args, **self.kwargs)
             ^^^^^^^^^^^^^^^^^^^^^^^^^^^^^^^^^^
  File "/code/.venv/lib/python3.12/site-packages/asgiref/sync.py", line 522, in thread_handler
    return func(*args, **kwargs)
           ^^^^^^^^^^^^^^^^^^^^^
  File "/code/.venv/lib/python3.12/site-packages/django/middleware/security.py", line 28, in process_request
    host = self.redirect_host or request.get_host()
                                 ^^^^^^^^^^^^^^^^^^
  File "/code/.venv/lib/python3.12/site-packages/django/http/request.py", line 151, in get_host
    raise DisallowedHost(msg)
django.core.exceptions.DisallowedHost: Invalid HTTP_HOST header: 'localhost:8000'. You may need to add 'localhost' to ALLOWED_HOSTS.
WARNING 2025-02-19 11:57:49,982 log 16 281473605300608 Bad Request: /health/
ERROR 2025-02-19 11:58:12,754 exception 17 281472838791552 Invalid HTTP_HOST header: 'localhost:8000'. You may need to add 'localhost' to ALLOWED_HOSTS.
Traceback (most recent call last):
  File "/code/.venv/lib/python3.12/site-packages/asgiref/sync.py", line 518, in thread_handler
    raise exc_info[1]
  File "/code/.venv/lib/python3.12/site-packages/django/core/handlers/exception.py", line 42, in inner
    response = await get_response(request)
               ^^^^^^^^^^^^^^^^^^^^^^^^^^^
  File "/code/.venv/lib/python3.12/site-packages/django/utils/deprecation.py", line 141, in __acall__
    response = await sync_to_async(
               ^^^^^^^^^^^^^^^^^^^^
  File "/code/.venv/lib/python3.12/site-packages/asgiref/sync.py", line 468, in __call__
    ret = await asyncio.shield(exec_coro)
          ^^^^^^^^^^^^^^^^^^^^^^^^^^^^^^^
  File "/usr/local/lib/python3.12/concurrent/futures/thread.py", line 59, in run
    result = self.fn(*self.args, **self.kwargs)
             ^^^^^^^^^^^^^^^^^^^^^^^^^^^^^^^^^^
  File "/code/.venv/lib/python3.12/site-packages/asgiref/sync.py", line 522, in thread_handler
    return func(*args, **kwargs)
           ^^^^^^^^^^^^^^^^^^^^^
  File "/code/.venv/lib/python3.12/site-packages/django/middleware/security.py", line 28, in process_request
    host = self.redirect_host or request.get_host()
                                 ^^^^^^^^^^^^^^^^^^
  File "/code/.venv/lib/python3.12/site-packages/django/http/request.py", line 151, in get_host
    raise DisallowedHost(msg)
django.core.exceptions.DisallowedHost: Invalid HTTP_HOST header: 'localhost:8000'. You may need to add 'localhost' to ALLOWED_HOSTS.
WARNING 2025-02-19 11:58:12,986 log 17 281472838791552 Bad Request: /health/
ERROR 2025-02-19 11:58:57,587 exception 17 281473376645504 Invalid HTTP_HOST header: 'localhost:8000'. You may need to add 'localhost' to ALLOWED_HOSTS.
Traceback (most recent call last):
  File "/code/.venv/lib/python3.12/site-packages/asgiref/sync.py", line 518, in thread_handler
    raise exc_info[1]
  File "/code/.venv/lib/python3.12/site-packages/django/core/handlers/exception.py", line 42, in inner
    response = await get_response(request)
               ^^^^^^^^^^^^^^^^^^^^^^^^^^^
  File "/code/.venv/lib/python3.12/site-packages/django/utils/deprecation.py", line 141, in __acall__
    response = await sync_to_async(
               ^^^^^^^^^^^^^^^^^^^^
  File "/code/.venv/lib/python3.12/site-packages/asgiref/sync.py", line 468, in __call__
    ret = await asyncio.shield(exec_coro)
          ^^^^^^^^^^^^^^^^^^^^^^^^^^^^^^^
  File "/usr/local/lib/python3.12/concurrent/futures/thread.py", line 59, in run
    result = self.fn(*self.args, **self.kwargs)
             ^^^^^^^^^^^^^^^^^^^^^^^^^^^^^^^^^^
  File "/code/.venv/lib/python3.12/site-packages/asgiref/sync.py", line 522, in thread_handler
    return func(*args, **kwargs)
           ^^^^^^^^^^^^^^^^^^^^^
  File "/code/.venv/lib/python3.12/site-packages/django/middleware/security.py", line 28, in process_request
    host = self.redirect_host or request.get_host()
                                 ^^^^^^^^^^^^^^^^^^
  File "/code/.venv/lib/python3.12/site-packages/django/http/request.py", line 151, in get_host
    raise DisallowedHost(msg)
django.core.exceptions.DisallowedHost: Invalid HTTP_HOST header: 'localhost:8000'. You may need to add 'localhost' to ALLOWED_HOSTS.
WARNING 2025-02-19 11:58:57,816 log 17 281473376645504 Bad Request: /health/
ERROR 2025-02-19 11:59:27,837 exception 17 281473376645504 Invalid HTTP_HOST header: 'localhost:8000'. You may need to add 'localhost' to ALLOWED_HOSTS.
Traceback (most recent call last):
  File "/code/.venv/lib/python3.12/site-packages/asgiref/sync.py", line 518, in thread_handler
    raise exc_info[1]
  File "/code/.venv/lib/python3.12/site-packages/django/core/handlers/exception.py", line 42, in inner
    response = await get_response(request)
               ^^^^^^^^^^^^^^^^^^^^^^^^^^^
  File "/code/.venv/lib/python3.12/site-packages/django/utils/deprecation.py", line 141, in __acall__
    response = await sync_to_async(
               ^^^^^^^^^^^^^^^^^^^^
  File "/code/.venv/lib/python3.12/site-packages/asgiref/sync.py", line 468, in __call__
    ret = await asyncio.shield(exec_coro)
          ^^^^^^^^^^^^^^^^^^^^^^^^^^^^^^^
  File "/usr/local/lib/python3.12/concurrent/futures/thread.py", line 59, in run
    result = self.fn(*self.args, **self.kwargs)
             ^^^^^^^^^^^^^^^^^^^^^^^^^^^^^^^^^^
  File "/code/.venv/lib/python3.12/site-packages/asgiref/sync.py", line 522, in thread_handler
    return func(*args, **kwargs)
           ^^^^^^^^^^^^^^^^^^^^^
  File "/code/.venv/lib/python3.12/site-packages/django/middleware/security.py", line 28, in process_request
    host = self.redirect_host or request.get_host()
                                 ^^^^^^^^^^^^^^^^^^
  File "/code/.venv/lib/python3.12/site-packages/django/http/request.py", line 151, in get_host
    raise DisallowedHost(msg)
django.core.exceptions.DisallowedHost: Invalid HTTP_HOST header: 'localhost:8000'. You may need to add 'localhost' to ALLOWED_HOSTS.
WARNING 2025-02-19 11:59:27,838 log 17 281473376645504 Bad Request: /health/
ERROR 2025-02-19 11:59:57,885 exception 18 281472807137664 Invalid HTTP_HOST header: 'localhost:8000'. You may need to add 'localhost' to ALLOWED_HOSTS.
Traceback (most recent call last):
  File "/code/.venv/lib/python3.12/site-packages/asgiref/sync.py", line 518, in thread_handler
    raise exc_info[1]
  File "/code/.venv/lib/python3.12/site-packages/django/core/handlers/exception.py", line 42, in inner
    response = await get_response(request)
               ^^^^^^^^^^^^^^^^^^^^^^^^^^^
  File "/code/.venv/lib/python3.12/site-packages/django/utils/deprecation.py", line 141, in __acall__
    response = await sync_to_async(
               ^^^^^^^^^^^^^^^^^^^^
  File "/code/.venv/lib/python3.12/site-packages/asgiref/sync.py", line 468, in __call__
    ret = await asyncio.shield(exec_coro)
          ^^^^^^^^^^^^^^^^^^^^^^^^^^^^^^^
  File "/usr/local/lib/python3.12/concurrent/futures/thread.py", line 59, in run
    result = self.fn(*self.args, **self.kwargs)
             ^^^^^^^^^^^^^^^^^^^^^^^^^^^^^^^^^^
  File "/code/.venv/lib/python3.12/site-packages/asgiref/sync.py", line 522, in thread_handler
    return func(*args, **kwargs)
           ^^^^^^^^^^^^^^^^^^^^^
  File "/code/.venv/lib/python3.12/site-packages/django/middleware/security.py", line 28, in process_request
    host = self.redirect_host or request.get_host()
                                 ^^^^^^^^^^^^^^^^^^
  File "/code/.venv/lib/python3.12/site-packages/django/http/request.py", line 151, in get_host
    raise DisallowedHost(msg)
django.core.exceptions.DisallowedHost: Invalid HTTP_HOST header: 'localhost:8000'. You may need to add 'localhost' to ALLOWED_HOSTS.
WARNING 2025-02-19 11:59:58,129 log 18 281472807137664 Bad Request: /health/
ERROR 2025-02-19 12:00:28,150 exception 17 281473376645504 Invalid HTTP_HOST header: 'localhost:8000'. You may need to add 'localhost' to ALLOWED_HOSTS.
Traceback (most recent call last):
  File "/code/.venv/lib/python3.12/site-packages/asgiref/sync.py", line 518, in thread_handler
    raise exc_info[1]
  File "/code/.venv/lib/python3.12/site-packages/django/core/handlers/exception.py", line 42, in inner
    response = await get_response(request)
               ^^^^^^^^^^^^^^^^^^^^^^^^^^^
  File "/code/.venv/lib/python3.12/site-packages/django/utils/deprecation.py", line 141, in __acall__
    response = await sync_to_async(
               ^^^^^^^^^^^^^^^^^^^^
  File "/code/.venv/lib/python3.12/site-packages/asgiref/sync.py", line 468, in __call__
    ret = await asyncio.shield(exec_coro)
          ^^^^^^^^^^^^^^^^^^^^^^^^^^^^^^^
  File "/usr/local/lib/python3.12/concurrent/futures/thread.py", line 59, in run
    result = self.fn(*self.args, **self.kwargs)
             ^^^^^^^^^^^^^^^^^^^^^^^^^^^^^^^^^^
  File "/code/.venv/lib/python3.12/site-packages/asgiref/sync.py", line 522, in thread_handler
    return func(*args, **kwargs)
           ^^^^^^^^^^^^^^^^^^^^^
  File "/code/.venv/lib/python3.12/site-packages/django/middleware/security.py", line 28, in process_request
    host = self.redirect_host or request.get_host()
                                 ^^^^^^^^^^^^^^^^^^
  File "/code/.venv/lib/python3.12/site-packages/django/http/request.py", line 151, in get_host
    raise DisallowedHost(msg)
django.core.exceptions.DisallowedHost: Invalid HTTP_HOST header: 'localhost:8000'. You may need to add 'localhost' to ALLOWED_HOSTS.
WARNING 2025-02-19 12:00:28,151 log 17 281473376645504 Bad Request: /health/
ERROR 2025-02-19 12:00:58,197 exception 17 281473376645504 Invalid HTTP_HOST header: 'localhost:8000'. You may need to add 'localhost' to ALLOWED_HOSTS.
Traceback (most recent call last):
  File "/code/.venv/lib/python3.12/site-packages/asgiref/sync.py", line 518, in thread_handler
    raise exc_info[1]
  File "/code/.venv/lib/python3.12/site-packages/django/core/handlers/exception.py", line 42, in inner
    response = await get_response(request)
               ^^^^^^^^^^^^^^^^^^^^^^^^^^^
  File "/code/.venv/lib/python3.12/site-packages/django/utils/deprecation.py", line 141, in __acall__
    response = await sync_to_async(
               ^^^^^^^^^^^^^^^^^^^^
  File "/code/.venv/lib/python3.12/site-packages/asgiref/sync.py", line 468, in __call__
    ret = await asyncio.shield(exec_coro)
          ^^^^^^^^^^^^^^^^^^^^^^^^^^^^^^^
  File "/usr/local/lib/python3.12/concurrent/futures/thread.py", line 59, in run
    result = self.fn(*self.args, **self.kwargs)
             ^^^^^^^^^^^^^^^^^^^^^^^^^^^^^^^^^^
  File "/code/.venv/lib/python3.12/site-packages/asgiref/sync.py", line 522, in thread_handler
    return func(*args, **kwargs)
           ^^^^^^^^^^^^^^^^^^^^^
  File "/code/.venv/lib/python3.12/site-packages/django/middleware/security.py", line 28, in process_request
    host = self.redirect_host or request.get_host()
                                 ^^^^^^^^^^^^^^^^^^
  File "/code/.venv/lib/python3.12/site-packages/django/http/request.py", line 151, in get_host
    raise DisallowedHost(msg)
django.core.exceptions.DisallowedHost: Invalid HTTP_HOST header: 'localhost:8000'. You may need to add 'localhost' to ALLOWED_HOSTS.
WARNING 2025-02-19 12:00:58,198 log 17 281473376645504 Bad Request: /health/
ERROR 2025-02-19 12:01:10,418 exception 16 281473366094208 Invalid HTTP_HOST header: 'localhost:8000'. You may need to add 'localhost' to ALLOWED_HOSTS.
Traceback (most recent call last):
  File "/code/.venv/lib/python3.12/site-packages/asgiref/sync.py", line 518, in thread_handler
    raise exc_info[1]
  File "/code/.venv/lib/python3.12/site-packages/django/core/handlers/exception.py", line 42, in inner
    response = await get_response(request)
               ^^^^^^^^^^^^^^^^^^^^^^^^^^^
  File "/code/.venv/lib/python3.12/site-packages/django/utils/deprecation.py", line 141, in __acall__
    response = await sync_to_async(
               ^^^^^^^^^^^^^^^^^^^^
  File "/code/.venv/lib/python3.12/site-packages/asgiref/sync.py", line 468, in __call__
    ret = await asyncio.shield(exec_coro)
          ^^^^^^^^^^^^^^^^^^^^^^^^^^^^^^^
  File "/usr/local/lib/python3.12/concurrent/futures/thread.py", line 59, in run
    result = self.fn(*self.args, **self.kwargs)
             ^^^^^^^^^^^^^^^^^^^^^^^^^^^^^^^^^^
  File "/code/.venv/lib/python3.12/site-packages/asgiref/sync.py", line 522, in thread_handler
    return func(*args, **kwargs)
           ^^^^^^^^^^^^^^^^^^^^^
  File "/code/.venv/lib/python3.12/site-packages/django/middleware/security.py", line 28, in process_request
    host = self.redirect_host or request.get_host()
                                 ^^^^^^^^^^^^^^^^^^
  File "/code/.venv/lib/python3.12/site-packages/django/http/request.py", line 151, in get_host
    raise DisallowedHost(msg)
django.core.exceptions.DisallowedHost: Invalid HTTP_HOST header: 'localhost:8000'. You may need to add 'localhost' to ALLOWED_HOSTS.
WARNING 2025-02-19 12:01:10,670 log 16 281473366094208 Bad Request: /health/
ERROR 2025-02-19 12:01:33,312 exception 19 281472773910912 Invalid HTTP_HOST header: 'localhost:8000'. You may need to add 'localhost' to ALLOWED_HOSTS.
Traceback (most recent call last):
  File "/code/.venv/lib/python3.12/site-packages/asgiref/sync.py", line 518, in thread_handler
    raise exc_info[1]
  File "/code/.venv/lib/python3.12/site-packages/django/core/handlers/exception.py", line 42, in inner
    response = await get_response(request)
               ^^^^^^^^^^^^^^^^^^^^^^^^^^^
  File "/code/.venv/lib/python3.12/site-packages/django/utils/deprecation.py", line 141, in __acall__
    response = await sync_to_async(
               ^^^^^^^^^^^^^^^^^^^^
  File "/code/.venv/lib/python3.12/site-packages/asgiref/sync.py", line 468, in __call__
    ret = await asyncio.shield(exec_coro)
          ^^^^^^^^^^^^^^^^^^^^^^^^^^^^^^^
  File "/usr/local/lib/python3.12/concurrent/futures/thread.py", line 59, in run
    result = self.fn(*self.args, **self.kwargs)
             ^^^^^^^^^^^^^^^^^^^^^^^^^^^^^^^^^^
  File "/code/.venv/lib/python3.12/site-packages/asgiref/sync.py", line 522, in thread_handler
    return func(*args, **kwargs)
           ^^^^^^^^^^^^^^^^^^^^^
  File "/code/.venv/lib/python3.12/site-packages/django/middleware/security.py", line 28, in process_request
    host = self.redirect_host or request.get_host()
                                 ^^^^^^^^^^^^^^^^^^
  File "/code/.venv/lib/python3.12/site-packages/django/http/request.py", line 151, in get_host
    raise DisallowedHost(msg)
django.core.exceptions.DisallowedHost: Invalid HTTP_HOST header: 'localhost:8000'. You may need to add 'localhost' to ALLOWED_HOSTS.
WARNING 2025-02-19 12:01:33,556 log 19 281472773910912 Bad Request: /health/
ERROR 2025-02-19 12:02:03,605 exception 18 281473411903872 Invalid HTTP_HOST header: 'localhost:8000'. You may need to add 'localhost' to ALLOWED_HOSTS.
Traceback (most recent call last):
  File "/code/.venv/lib/python3.12/site-packages/asgiref/sync.py", line 518, in thread_handler
    raise exc_info[1]
  File "/code/.venv/lib/python3.12/site-packages/django/core/handlers/exception.py", line 42, in inner
    response = await get_response(request)
               ^^^^^^^^^^^^^^^^^^^^^^^^^^^
  File "/code/.venv/lib/python3.12/site-packages/django/utils/deprecation.py", line 141, in __acall__
    response = await sync_to_async(
               ^^^^^^^^^^^^^^^^^^^^
  File "/code/.venv/lib/python3.12/site-packages/asgiref/sync.py", line 468, in __call__
    ret = await asyncio.shield(exec_coro)
          ^^^^^^^^^^^^^^^^^^^^^^^^^^^^^^^
  File "/usr/local/lib/python3.12/concurrent/futures/thread.py", line 59, in run
    result = self.fn(*self.args, **self.kwargs)
             ^^^^^^^^^^^^^^^^^^^^^^^^^^^^^^^^^^
  File "/code/.venv/lib/python3.12/site-packages/asgiref/sync.py", line 522, in thread_handler
    return func(*args, **kwargs)
           ^^^^^^^^^^^^^^^^^^^^^
  File "/code/.venv/lib/python3.12/site-packages/django/middleware/security.py", line 28, in process_request
    host = self.redirect_host or request.get_host()
                                 ^^^^^^^^^^^^^^^^^^
  File "/code/.venv/lib/python3.12/site-packages/django/http/request.py", line 151, in get_host
    raise DisallowedHost(msg)
django.core.exceptions.DisallowedHost: Invalid HTTP_HOST header: 'localhost:8000'. You may need to add 'localhost' to ALLOWED_HOSTS.
WARNING 2025-02-19 12:02:03,844 log 18 281473411903872 Bad Request: /health/
ERROR 2025-02-19 12:02:33,885 exception 18 281473411903872 Invalid HTTP_HOST header: 'localhost:8000'. You may need to add 'localhost' to ALLOWED_HOSTS.
Traceback (most recent call last):
  File "/code/.venv/lib/python3.12/site-packages/asgiref/sync.py", line 518, in thread_handler
    raise exc_info[1]
  File "/code/.venv/lib/python3.12/site-packages/django/core/handlers/exception.py", line 42, in inner
    response = await get_response(request)
               ^^^^^^^^^^^^^^^^^^^^^^^^^^^
  File "/code/.venv/lib/python3.12/site-packages/django/utils/deprecation.py", line 141, in __acall__
    response = await sync_to_async(
               ^^^^^^^^^^^^^^^^^^^^
  File "/code/.venv/lib/python3.12/site-packages/asgiref/sync.py", line 468, in __call__
    ret = await asyncio.shield(exec_coro)
          ^^^^^^^^^^^^^^^^^^^^^^^^^^^^^^^
  File "/usr/local/lib/python3.12/concurrent/futures/thread.py", line 59, in run
    result = self.fn(*self.args, **self.kwargs)
             ^^^^^^^^^^^^^^^^^^^^^^^^^^^^^^^^^^
  File "/code/.venv/lib/python3.12/site-packages/asgiref/sync.py", line 522, in thread_handler
    return func(*args, **kwargs)
           ^^^^^^^^^^^^^^^^^^^^^
  File "/code/.venv/lib/python3.12/site-packages/django/middleware/security.py", line 28, in process_request
    host = self.redirect_host or request.get_host()
                                 ^^^^^^^^^^^^^^^^^^
  File "/code/.venv/lib/python3.12/site-packages/django/http/request.py", line 151, in get_host
    raise DisallowedHost(msg)
django.core.exceptions.DisallowedHost: Invalid HTTP_HOST header: 'localhost:8000'. You may need to add 'localhost' to ALLOWED_HOSTS.
WARNING 2025-02-19 12:02:33,886 log 18 281473411903872 Bad Request: /health/
ERROR 2025-02-19 12:02:45,304 exception 19 281473455223168 Invalid HTTP_HOST header: 'localhost:8000'. You may need to add 'localhost' to ALLOWED_HOSTS.
Traceback (most recent call last):
  File "/code/.venv/lib/python3.12/site-packages/asgiref/sync.py", line 518, in thread_handler
    raise exc_info[1]
  File "/code/.venv/lib/python3.12/site-packages/django/core/handlers/exception.py", line 42, in inner
    response = await get_response(request)
               ^^^^^^^^^^^^^^^^^^^^^^^^^^^
  File "/code/.venv/lib/python3.12/site-packages/django/utils/deprecation.py", line 141, in __acall__
    response = await sync_to_async(
               ^^^^^^^^^^^^^^^^^^^^
  File "/code/.venv/lib/python3.12/site-packages/asgiref/sync.py", line 468, in __call__
    ret = await asyncio.shield(exec_coro)
          ^^^^^^^^^^^^^^^^^^^^^^^^^^^^^^^
  File "/usr/local/lib/python3.12/concurrent/futures/thread.py", line 59, in run
    result = self.fn(*self.args, **self.kwargs)
             ^^^^^^^^^^^^^^^^^^^^^^^^^^^^^^^^^^
  File "/code/.venv/lib/python3.12/site-packages/asgiref/sync.py", line 522, in thread_handler
    return func(*args, **kwargs)
           ^^^^^^^^^^^^^^^^^^^^^
  File "/code/.venv/lib/python3.12/site-packages/django/middleware/security.py", line 28, in process_request
    host = self.redirect_host or request.get_host()
                                 ^^^^^^^^^^^^^^^^^^
  File "/code/.venv/lib/python3.12/site-packages/django/http/request.py", line 151, in get_host
    raise DisallowedHost(msg)
django.core.exceptions.DisallowedHost: Invalid HTTP_HOST header: 'localhost:8000'. You may need to add 'localhost' to ALLOWED_HOSTS.
WARNING 2025-02-19 12:02:45,571 log 19 281473455223168 Bad Request: /health/
ERROR 2025-02-19 12:03:05,138 exception 19 281473455223168 Invalid HTTP_HOST header: 'localhost:8000'. You may need to add 'localhost' to ALLOWED_HOSTS.
Traceback (most recent call last):
  File "/code/.venv/lib/python3.12/site-packages/asgiref/sync.py", line 518, in thread_handler
    raise exc_info[1]
  File "/code/.venv/lib/python3.12/site-packages/django/core/handlers/exception.py", line 42, in inner
    response = await get_response(request)
               ^^^^^^^^^^^^^^^^^^^^^^^^^^^
  File "/code/.venv/lib/python3.12/site-packages/django/utils/deprecation.py", line 141, in __acall__
    response = await sync_to_async(
               ^^^^^^^^^^^^^^^^^^^^
  File "/code/.venv/lib/python3.12/site-packages/asgiref/sync.py", line 468, in __call__
    ret = await asyncio.shield(exec_coro)
          ^^^^^^^^^^^^^^^^^^^^^^^^^^^^^^^
  File "/usr/local/lib/python3.12/concurrent/futures/thread.py", line 59, in run
    result = self.fn(*self.args, **self.kwargs)
             ^^^^^^^^^^^^^^^^^^^^^^^^^^^^^^^^^^
  File "/code/.venv/lib/python3.12/site-packages/asgiref/sync.py", line 522, in thread_handler
    return func(*args, **kwargs)
           ^^^^^^^^^^^^^^^^^^^^^
  File "/code/.venv/lib/python3.12/site-packages/django/middleware/security.py", line 28, in process_request
    host = self.redirect_host or request.get_host()
                                 ^^^^^^^^^^^^^^^^^^
  File "/code/.venv/lib/python3.12/site-packages/django/http/request.py", line 151, in get_host
    raise DisallowedHost(msg)
django.core.exceptions.DisallowedHost: Invalid HTTP_HOST header: 'localhost:8000'. You may need to add 'localhost' to ALLOWED_HOSTS.
WARNING 2025-02-19 12:03:05,139 log 19 281473455223168 Bad Request: /health/
ERROR 2025-02-19 12:03:30,246 exception 17 281473164767616 Invalid HTTP_HOST header: 'localhost:8000'. You may need to add 'localhost' to ALLOWED_HOSTS.
Traceback (most recent call last):
  File "/code/.venv/lib/python3.12/site-packages/asgiref/sync.py", line 518, in thread_handler
    raise exc_info[1]
  File "/code/.venv/lib/python3.12/site-packages/django/core/handlers/exception.py", line 42, in inner
    response = await get_response(request)
               ^^^^^^^^^^^^^^^^^^^^^^^^^^^
  File "/code/.venv/lib/python3.12/site-packages/django/utils/deprecation.py", line 141, in __acall__
    response = await sync_to_async(
               ^^^^^^^^^^^^^^^^^^^^
  File "/code/.venv/lib/python3.12/site-packages/asgiref/sync.py", line 468, in __call__
    ret = await asyncio.shield(exec_coro)
          ^^^^^^^^^^^^^^^^^^^^^^^^^^^^^^^
  File "/usr/local/lib/python3.12/concurrent/futures/thread.py", line 59, in run
    result = self.fn(*self.args, **self.kwargs)
             ^^^^^^^^^^^^^^^^^^^^^^^^^^^^^^^^^^
  File "/code/.venv/lib/python3.12/site-packages/asgiref/sync.py", line 522, in thread_handler
    return func(*args, **kwargs)
           ^^^^^^^^^^^^^^^^^^^^^
  File "/code/.venv/lib/python3.12/site-packages/django/middleware/security.py", line 28, in process_request
    host = self.redirect_host or request.get_host()
                                 ^^^^^^^^^^^^^^^^^^
  File "/code/.venv/lib/python3.12/site-packages/django/http/request.py", line 151, in get_host
    raise DisallowedHost(msg)
django.core.exceptions.DisallowedHost: Invalid HTTP_HOST header: 'localhost:8000'. You may need to add 'localhost' to ALLOWED_HOSTS.
WARNING 2025-02-19 12:03:30,505 log 17 281473164767616 Bad Request: /health/
ERROR 2025-02-19 12:03:53,216 exception 17 281473164767616 Invalid HTTP_HOST header: 'localhost:8000'. You may need to add 'localhost' to ALLOWED_HOSTS.
Traceback (most recent call last):
  File "/code/.venv/lib/python3.12/site-packages/asgiref/sync.py", line 518, in thread_handler
    raise exc_info[1]
  File "/code/.venv/lib/python3.12/site-packages/django/core/handlers/exception.py", line 42, in inner
    response = await get_response(request)
               ^^^^^^^^^^^^^^^^^^^^^^^^^^^
  File "/code/.venv/lib/python3.12/site-packages/django/utils/deprecation.py", line 141, in __acall__
    response = await sync_to_async(
               ^^^^^^^^^^^^^^^^^^^^
  File "/code/.venv/lib/python3.12/site-packages/asgiref/sync.py", line 468, in __call__
    ret = await asyncio.shield(exec_coro)
          ^^^^^^^^^^^^^^^^^^^^^^^^^^^^^^^
  File "/usr/local/lib/python3.12/concurrent/futures/thread.py", line 59, in run
    result = self.fn(*self.args, **self.kwargs)
             ^^^^^^^^^^^^^^^^^^^^^^^^^^^^^^^^^^
  File "/code/.venv/lib/python3.12/site-packages/asgiref/sync.py", line 522, in thread_handler
    return func(*args, **kwargs)
           ^^^^^^^^^^^^^^^^^^^^^
  File "/code/.venv/lib/python3.12/site-packages/django/middleware/security.py", line 28, in process_request
    host = self.redirect_host or request.get_host()
                                 ^^^^^^^^^^^^^^^^^^
  File "/code/.venv/lib/python3.12/site-packages/django/http/request.py", line 151, in get_host
    raise DisallowedHost(msg)
django.core.exceptions.DisallowedHost: Invalid HTTP_HOST header: 'localhost:8000'. You may need to add 'localhost' to ALLOWED_HOSTS.
WARNING 2025-02-19 12:03:53,217 log 17 281473164767616 Bad Request: /health/
ERROR 2025-02-19 12:04:23,265 exception 17 281473164767616 Invalid HTTP_HOST header: 'localhost:8000'. You may need to add 'localhost' to ALLOWED_HOSTS.
Traceback (most recent call last):
  File "/code/.venv/lib/python3.12/site-packages/asgiref/sync.py", line 518, in thread_handler
    raise exc_info[1]
  File "/code/.venv/lib/python3.12/site-packages/django/core/handlers/exception.py", line 42, in inner
    response = await get_response(request)
               ^^^^^^^^^^^^^^^^^^^^^^^^^^^
  File "/code/.venv/lib/python3.12/site-packages/django/utils/deprecation.py", line 141, in __acall__
    response = await sync_to_async(
               ^^^^^^^^^^^^^^^^^^^^
  File "/code/.venv/lib/python3.12/site-packages/asgiref/sync.py", line 468, in __call__
    ret = await asyncio.shield(exec_coro)
          ^^^^^^^^^^^^^^^^^^^^^^^^^^^^^^^
  File "/usr/local/lib/python3.12/concurrent/futures/thread.py", line 59, in run
    result = self.fn(*self.args, **self.kwargs)
             ^^^^^^^^^^^^^^^^^^^^^^^^^^^^^^^^^^
  File "/code/.venv/lib/python3.12/site-packages/asgiref/sync.py", line 522, in thread_handler
    return func(*args, **kwargs)
           ^^^^^^^^^^^^^^^^^^^^^
  File "/code/.venv/lib/python3.12/site-packages/django/middleware/security.py", line 28, in process_request
    host = self.redirect_host or request.get_host()
                                 ^^^^^^^^^^^^^^^^^^
  File "/code/.venv/lib/python3.12/site-packages/django/http/request.py", line 151, in get_host
    raise DisallowedHost(msg)
django.core.exceptions.DisallowedHost: Invalid HTTP_HOST header: 'localhost:8000'. You may need to add 'localhost' to ALLOWED_HOSTS.
WARNING 2025-02-19 12:04:23,266 log 17 281473164767616 Bad Request: /health/
WARNING 2025-02-19 12:07:58,274 log 15 281473204494368 Not Found: /api
WARNING 2025-02-19 12:08:04,340 log 17 281473204494368 Not Found: /health
WARNING 2025-02-19 12:08:23,398 log 18 281473204494368 Not Found: /health
WARNING 2025-02-19 12:08:51,324 log 17 281473204494368 Not Found: /health
WARNING 2025-02-19 12:09:06,444 log 18 281473204494368 Unauthorized: /api/
WARNING 2025-02-19 12:09:10,814 log 18 281473204494368 Not Found: /api
WARNING 2025-02-19 12:09:16,513 log 16 281473204494368 Not Found: /docs
WARNING 2025-02-19 12:09:18,092 log 16 281473204494368 Not Found: /docs/
WARNING 2025-02-19 12:09:21,282 log 18 281473204494368 Not Found: /
WARNING 2025-02-19 12:09:32,263 log 17 281473204494368 Unauthorized: /api/
Loading Comment model module
Registering Comment model with app_label: conduit_comments
Comment model class defined
Loading Article model module
Registering Article model with app_label: conduit_articles
Module path: conduit.articles.models
Article model class defined
Loading Comment model module
Registering Comment model with app_label: conduit_comments
Comment model class defined
Loading Article model module
Registering Article model with app_label: conduit_articles
Module path: conduit.articles.models
Article model class defined
Loading Comment model module
Registering Comment model with app_label: conduit_comments
Comment model class defined
Loading Article model module
Registering Article model with app_label: conduit_articles
Module path: conduit.articles.models
Article model class defined
Loading Comment model module
Registering Comment model with app_label: conduit_comments
Comment model class defined
Loading Article model module
Registering Article model with app_label: conduit_articles
Module path: conduit.articles.models
Article model class defined
Loading Comment model module
Registering Comment model with app_label: conduit_comments
Comment model class defined
Loading Article model module
Registering Article model with app_label: conduit_articles
Module path: conduit.articles.models
Article model class defined
Loading Comment model module
Registering Comment model with app_label: conduit_comments
Comment model class defined
Loading Article model module
Registering Article model with app_label: conduit_articles
Module path: conduit.articles.models
Article model class defined
Loading Comment model module
Registering Comment model with app_label: conduit_comments
Comment model class defined
Loading Article model module
Registering Article model with app_label: conduit_articles
Module path: conduit.articles.models
Article model class defined
Loading Comment model module
Registering Comment model with app_label: conduit_comments
Comment model class defined
Loading Article model module
Registering Article model with app_label: conduit_articles
Module path: conduit.articles.models
Article model class defined
Loading Comment model module
Registering Comment model with app_label: conduit_comments
Comment model class defined
Loading Article model module
Registering Article model with app_label: conduit_articles
Module path: conduit.articles.models
Article model class defined
DEBUG 2025-02-19 14:38:13,211 models 17 281473166557216 Loading Comment model module
DEBUG 2025-02-19 14:38:13,211 models 17 281473166557216 Registering Comment model with app_label: conduit_comments
DEBUG 2025-02-19 14:38:13,212 models 17 281473166557216 Comment model class defined
DEBUG 2025-02-19 14:38:13,212 models 17 281473166557216 Loading Article model module
DEBUG 2025-02-19 14:38:13,212 models 17 281473166557216 Registering Article model with app_label: conduit_articles
DEBUG 2025-02-19 14:38:13,212 models 17 281473166557216 Module path: conduit.articles.models
DEBUG 2025-02-19 14:38:13,212 models 17 281473166557216 Article model class defined
DEBUG 2025-02-19 14:38:13,253 models 18 281473166557216 Loading Comment model module
DEBUG 2025-02-19 14:38:13,253 models 18 281473166557216 Registering Comment model with app_label: conduit_comments
DEBUG 2025-02-19 14:38:13,253 models 18 281473166557216 Comment model class defined
DEBUG 2025-02-19 14:38:13,253 models 18 281473166557216 Loading Article model module
DEBUG 2025-02-19 14:38:13,253 models 18 281473166557216 Registering Article model with app_label: conduit_articles
DEBUG 2025-02-19 14:38:13,253 models 18 281473166557216 Module path: conduit.articles.models
DEBUG 2025-02-19 14:38:13,254 models 18 281473166557216 Article model class defined
DEBUG 2025-02-19 14:38:13,262 models 20 281473166557216 Loading Comment model module
DEBUG 2025-02-19 14:38:13,262 models 20 281473166557216 Registering Comment model with app_label: conduit_comments
DEBUG 2025-02-19 14:38:13,262 models 20 281473166557216 Comment model class defined
DEBUG 2025-02-19 14:38:13,262 models 19 281473166557216 Loading Comment model module
DEBUG 2025-02-19 14:38:13,263 models 19 281473166557216 Registering Comment model with app_label: conduit_comments
DEBUG 2025-02-19 14:38:13,263 models 19 281473166557216 Comment model class defined
DEBUG 2025-02-19 14:38:13,263 models 20 281473166557216 Loading Article model module
DEBUG 2025-02-19 14:38:13,263 models 20 281473166557216 Registering Article model with app_label: conduit_articles
DEBUG 2025-02-19 14:38:13,263 models 20 281473166557216 Module path: conduit.articles.models
DEBUG 2025-02-19 14:38:13,263 models 19 281473166557216 Loading Article model module
DEBUG 2025-02-19 14:38:13,263 models 19 281473166557216 Registering Article model with app_label: conduit_articles
DEBUG 2025-02-19 14:38:13,263 models 19 281473166557216 Module path: conduit.articles.models
DEBUG 2025-02-19 14:38:13,263 models 20 281473166557216 Article model class defined
DEBUG 2025-02-19 14:38:13,263 models 19 281473166557216 Article model class defined
DEBUG 2025-02-19 14:51:40,006 models 161 281473166557216 Loading Comment model module
DEBUG 2025-02-19 14:51:40,007 models 161 281473166557216 Registering Comment model with app_label: conduit_comments
DEBUG 2025-02-19 14:51:40,007 models 161 281473166557216 Comment model class defined
DEBUG 2025-02-19 14:51:40,008 models 161 281473166557216 Loading Article model module
DEBUG 2025-02-19 14:51:40,008 models 161 281473166557216 Registering Article model with app_label: conduit_articles
DEBUG 2025-02-19 14:51:40,008 models 161 281473166557216 Module path: conduit.articles.models
DEBUG 2025-02-19 14:51:40,008 models 161 281473166557216 Article model class defined
DEBUG 2025-02-19 15:27:56,520 models 597 281473166557216 Loading Comment model module
DEBUG 2025-02-19 15:27:56,520 models 597 281473166557216 Registering Comment model with app_label: conduit_comments
DEBUG 2025-02-19 15:27:56,520 models 597 281473166557216 Comment model class defined
DEBUG 2025-02-19 15:27:56,521 models 597 281473166557216 Loading Article model module
DEBUG 2025-02-19 15:27:56,521 models 597 281473166557216 Registering Article model with app_label: conduit_articles
DEBUG 2025-02-19 15:27:56,521 models 597 281473166557216 Module path: conduit.articles.models
DEBUG 2025-02-19 15:27:56,521 models 597 281473166557216 Article model class defined
DEBUG 2025-02-19 15:27:56,522 models 596 281473166557216 Loading Comment model module
DEBUG 2025-02-19 15:27:56,522 models 596 281473166557216 Registering Comment model with app_label: conduit_comments
DEBUG 2025-02-19 15:27:56,522 models 596 281473166557216 Comment model class defined
DEBUG 2025-02-19 15:27:56,522 models 596 281473166557216 Loading Article model module
DEBUG 2025-02-19 15:27:56,522 models 596 281473166557216 Registering Article model with app_label: conduit_articles
DEBUG 2025-02-19 15:27:56,522 models 596 281473166557216 Module path: conduit.articles.models
DEBUG 2025-02-19 15:27:56,523 models 596 281473166557216 Article model class defined
DEBUG 2025-02-19 16:05:31,402 models 1025 281473166557216 Loading Comment model module
DEBUG 2025-02-19 16:05:31,402 models 1025 281473166557216 Registering Comment model with app_label: conduit_comments
DEBUG 2025-02-19 16:05:31,402 models 1025 281473166557216 Comment model class defined
DEBUG 2025-02-19 16:05:31,402 models 1027 281473166557216 Loading Comment model module
DEBUG 2025-02-19 16:05:31,402 models 1027 281473166557216 Registering Comment model with app_label: conduit_comments
DEBUG 2025-02-19 16:05:31,402 models 1025 281473166557216 Loading Article model module
DEBUG 2025-02-19 16:05:31,402 models 1025 281473166557216 Registering Article model with app_label: conduit_articles
DEBUG 2025-02-19 16:05:31,402 models 1025 281473166557216 Module path: conduit.articles.models
DEBUG 2025-02-19 16:05:31,402 models 1027 281473166557216 Comment model class defined
DEBUG 2025-02-19 16:05:31,401 models 1026 281473166557216 Loading Comment model module
DEBUG 2025-02-19 16:05:31,403 models 1028 281473166557216 Loading Comment model module
DEBUG 2025-02-19 16:05:31,403 models 1028 281473166557216 Registering Comment model with app_label: conduit_comments
DEBUG 2025-02-19 16:05:31,403 models 1026 281473166557216 Registering Comment model with app_label: conduit_comments
DEBUG 2025-02-19 16:05:31,403 models 1028 281473166557216 Comment model class defined
DEBUG 2025-02-19 16:05:31,403 models 1025 281473166557216 Article model class defined
DEBUG 2025-02-19 16:05:31,403 models 1026 281473166557216 Comment model class defined
DEBUG 2025-02-19 16:05:31,404 models 1028 281473166557216 Loading Article model module
DEBUG 2025-02-19 16:05:31,404 models 1027 281473166557216 Loading Article model module
DEBUG 2025-02-19 16:05:31,404 models 1028 281473166557216 Registering Article model with app_label: conduit_articles
DEBUG 2025-02-19 16:05:31,404 models 1027 281473166557216 Registering Article model with app_label: conduit_articles
DEBUG 2025-02-19 16:05:31,404 models 1028 281473166557216 Module path: conduit.articles.models
DEBUG 2025-02-19 16:05:31,404 models 1026 281473166557216 Loading Article model module
DEBUG 2025-02-19 16:05:31,404 models 1027 281473166557216 Module path: conduit.articles.models
DEBUG 2025-02-19 16:05:31,404 models 1028 281473166557216 Article model class defined
DEBUG 2025-02-19 16:05:31,404 models 1026 281473166557216 Registering Article model with app_label: conduit_articles
DEBUG 2025-02-19 16:05:31,404 models 1027 281473166557216 Article model class defined
DEBUG 2025-02-19 16:05:31,404 models 1026 281473166557216 Module path: conduit.articles.models
DEBUG 2025-02-19 16:05:31,405 models 1026 281473166557216 Article model class defined
